<?xml version="1.0" encoding="utf-8"?>
<robot name="wheelchair_des" xmlns:xacro="http://www.ros.org/wiki/xacro">
  
  <xacro:include filename="$(find wheelchair_des)/urdf/wheelchair_materials.xacro"/>
  
  <link name="base_footprint">
  </link>
  
  <link
    name="base_link">
    <inertial>
      <origin
        xyz="-0.080987486271254 -0.0296596801365287 0.0111666325817064"
        rpy="0 0 0" />
      <mass
        value="25.0244128773916" />
      <inertia
        ixx="0.471634336298249"
        ixy="0.00824343931442097"
        ixz="-0.0193729845601956"
        iyy="0.44356953512133"
        iyz="3.60464949398891E-06"
        izz="0.497492570615017" />
    </inertial>
    <visual>
      <origin
        xyz="0 0 0"
        rpy="0 0 0" />
      <geometry>
        <mesh
          filename="package://wheelchair_des/meshes/base_link.STL" />
      </geometry>
      <material
        name="white"/>
    </visual>
    <collision>
      <origin
        xyz="0 0 0"
        rpy="0 0 0" />
      <geometry>
        <mesh
          filename="package://wheelchair_des/meshes/base_link.STL" />
      </geometry>
    </collision>
  </link>

  <joint
    name="base_joint"
    type="fixed">
    <origin
      xyz="0 0 0.43240025653114"
      rpy="0 0 0" />
    <parent
      link="base_footprint" />
    <child
      link="base_link" />
    <axis
      xyz="0 0 0" />
  </joint>
  
  <link
    name="caster_left_link">
    <inertial>
      <origin
        xyz="0 -0.0599999999999999 0"
        rpy="0 0 0" />
      <mass
        value="4.40934690008729" />
      <inertia
        ixx="0.0210319896084761"
        ixy="1.24964759959585E-34"
        ixz="-5.70593071526157E-24"
        iyy="0.0368982021708161"
        iyz="2.35816819395541E-19"
        izz="0.0210319896084761" />
    </inertial>
    <visual>
      <origin
        xyz="0 0 0"
        rpy="0 0 0" />
      <geometry>
        <mesh
          filename="package://wheelchair_des/meshes/caster_left_link.STL" />
      </geometry>
      <material
        name="orange"/>
    </visual>
    <collision>
      <origin
        xyz="0 0 0"
        rpy="0 0 0" />
      <geometry>
        <mesh
          filename="package://wheelchair_des/meshes/caster_left_link.STL" />
      </geometry>
    </collision>
  </link>

  <joint
    name="caster_left_joint"
    type="continuous">
    <origin
      xyz="0.32884 0.33655 -0.3024"
      rpy="0 0 0" />
    <parent
      link="base_link" />
    <child
      link="caster_left_link" />
    <axis
      xyz="0 1 0" />
  </joint>
  
  <link
    name="caster_right_link">
    <inertial>
      <origin
        xyz="0 0.06 0"
        rpy="0 0 0" />
      <mass
        value="4.40934690008729" />
      <inertia
        ixx="0.0210319896084761"
        ixy="2.11758236813575E-20"
        ixz="-8.18747255346068E-24"
        iyy="0.0368982021708161"
        iyz="2.37011509461079E-19"
        izz="0.0210319896084761" />
    </inertial>
    <visual>
      <origin
        xyz="0 0 0"
        rpy="0 0 0" />
      <geometry>
        <mesh
          filename="package://wheelchair_des/meshes/caster_right_link.STL" />
      </geometry>
      <material
        name="orange"/>
    </visual>
    <collision>
      <origin
        xyz="0 0 0"
        rpy="0 0 0" />
      <geometry>
        <mesh
          filename="package://wheelchair_des/meshes/caster_right_link.STL" />
      </geometry>
    </collision>
  </link>
  
  <joint
    name="caster_right_joint"
    type="continuous">
    <origin
      xyz="0.32884 -0.33655 -0.3024"
      rpy="0 0 0" />
    <parent
      link="base_link" />
    <child
      link="caster_right_link" />
    <axis
      xyz="0 1 0" />
  </joint>
  
  <link
    name="wheel_left_link">
    <inertial>
      <origin
        xyz="0 -0.0515 0"
        rpy="0 0 0" />
      <mass
        value="7.16080210982417" />
      <inertia
        ixx="0.0580966446914578"
        ixy="4.23516473627149E-19"
        ixz="4.06548409937926E-23"
        iyy="0.109587758725363"
        iyz="-1.07273615672581E-18"
        izz="0.0580966446914578" />
    </inertial>
    <visual>
      <origin
        xyz="0 0 0"
        rpy="0 0 0" />
      <geometry>
        <mesh
          filename="package://wheelchair_des/meshes/wheel_left_link.STL" />
      </geometry>
      <material
        name="orange"/>
    </visual>
    <collision>
      <origin
        xyz="0 0 0"
        rpy="0 0 0" />
      <geometry>
        <mesh
          filename="package://wheelchair_des/meshes/wheel_left_link.STL" />
      </geometry>
    </collision>
  </link>
  
  <joint
    name="wheel_left_joint"
    type="continuous">
    <origin
      xyz="-0.27524 0.33475 -0.2569"
      rpy="0 0 0" />
    <parent
      link="base_link" />
    <child
      link="wheel_left_link" />
    <axis
      xyz="0 1 0" />
  </joint>
  
  <link
    name="wheel_right_link">
    <inertial>
      <origin
        xyz="-1.73472347597681E-18 0.0515 0"
        rpy="0 0 0" />
      <mass
        value="7.16080210982418" />
      <inertia
        ixx="0.0580966446914578"
        ixy="2.11758236813575E-19"
        ixz="4.06548409937907E-23"
        iyy="0.109587758725363"
        iyz="-1.07273719070158E-18"
        izz="0.0580966446914578" />
    </inertial>
    <visual>
      <origin
        xyz="0 0 0"
        rpy="0 0 0" />
      <geometry>
        <mesh
          filename="package://wheelchair_des/meshes/wheel_right_link.STL" />
      </geometry>
      <material
        name="orange"/>
    </visual>
    <collision>
      <origin
        xyz="0 0 0"
        rpy="0 0 0" />
      <geometry>
        <mesh
          filename="package://wheelchair_des/meshes/wheel_right_link.STL" />
      </geometry>
    </collision>
  </link>
  
  <joint
    name="wheel_right_joint"
    type="continuous">
    <origin
      xyz="-0.27524 -0.33525 -0.2569"
      rpy="0 0 0" />
    <parent
      link="base_link" />
    <child
      link="wheel_right_link" />
    <axis
      xyz="0 1 0" />
  </joint>
  
  <link
    name="base_scan">
    <inertial>
      <origin
        xyz="0 6.93889390390723E-18 0.00122854280541004"
        rpy="0 0 0" />
      <mass
        value="0.173952291044052" />
      <inertia
        ixx="8.31356173880308E-05"
        ixy="2.28999336772898E-26"
        ixz="0"
        iyy="8.31356173880308E-05"
        iyz="1.14659736808138E-21"
        izz="0.000118430701922264" />
    </inertial>
    <visual>
      <origin
        xyz="0 0 0"
        rpy="0 0 0" />
      <geometry>
        <mesh
          filename="package://wheelchair_des/meshes/base_scan.STL" />
      </geometry>
      <material
        name="red"/>
    </visual>
    <collision>
      <origin
        xyz="0 0 0"
        rpy="0 0 0" />
      <geometry>
        <mesh
          filename="package://wheelchair_des/meshes/base_scan.STL" />
      </geometry>
    </collision>
  </link>
  
  <joint
    name="scan_joint"
    type="fixed">
    <origin
      xyz="0.4188 -0.25 0.1126"
      rpy="0 0 3.14" />
    <parent
      link="base_link" />
    <child
      link="base_scan" />
    <axis
      xyz="0 0 0" />
  </joint>
  
  <link
    name="imu_link">
    <inertial>
      <origin
        xyz="3.46944695195361E-18 2.77555756156289E-17 -0.004"
        rpy="0 0 0" />
      <mass
        value="0.00320000000000001" />
      <inertia
        ixx="1.23733333333334E-07"
        ixy="-1.19248121757618E-23"
        ixz="-5.05085746447727E-25"
        iyy="1.23733333333334E-07"
        iyz="-4.2898617694675E-40"
        izz="2.13333333333334E-07" />
    </inertial>
    <visual>
      <origin
        xyz="0 0 0"
        rpy="0 0 0" />
      <geometry>
        <mesh
          filename="package://wheelchair_des/meshes/imu_link.STL" />
      </geometry>
      <material
        name="red"/>
    </visual>
    <collision>
      <origin
        xyz="0 0 0"
        rpy="0 0 0" />
      <geometry>
        <mesh
          filename="package://wheelchair_des/meshes/imu_link.STL" />
      </geometry>
    </collision>
  </link>
  
  <joint
    name="imu_joint"
    type="fixed">
    <origin
      xyz="-0.26076 -0.01 0.0069127"
      rpy="0 0 0" />
    <parent
      link="base_link" />
    <child
      link="imu_link" />
    <axis
      xyz="0 0 0" />
  </joint>
</robot>